<?xml version="1.0"?>
<robot xmlns:xacro="http://www.ros.org/wiki/xacro">

    <xacro:include filename="inertial_macros.xacro"/>

    <material name="white">
        <color rgba="1 1 1 0.8"/>
    </material>
    <material name="teal">
        <color rgba="0 0.5 0.6 0.8"/>
    </material>
    <material name="black">
        <color rgba="0 0 0 0.8"/>
    </material>

<!-- BASE LINK -->
    <link name="base_link">
    </link>

<!-- COMMON BODY -->
    <joint name="chassis_joint" type="fixed">
        <parent link="base_link"/>
        <child link="chassis"/>
        <origin xyz="0 0 0"/>
    </joint>

    <link name="chassis">
        <visual>
            <origin xyz="0 0 0.14"/>
            <geometry>
                <box size="0.76 0.52 0.28"/>
            </geometry>
            <material name="white"/>
        </visual>
        <collision>
        <origin xyz="0 0 0.14"/>
            <geometry>
                <box size="0.76 0.52 0.28"/>
            </geometry>
        </collision>
        <xacro:inertial_box mass="0.5" x="0.76" y="0.52" z="0.28">
            <origin xyz="0 0 0.14" rpy="0 0 0"/>
        </xacro:inertial_box>
    </link>

<!-- BACK LEFT LEG -->
<joint name="back_left_hip_joint" type="revolute">
    <parent link="base_link"/>
    <child link="back_left_hip"/>
    <origin xyz="-0.3 0.25 0.1" rpy="${pi/2} 0 0"/>
    <axis xyz="-1 0 0"/>
    <limit lower="${pi/2}" upper="${pi/4}" effort="0.1" velocity="0.1"/>
</joint>

<link name="back_left_hip">
    <visual>
        <origin xyz="0 0 0" rpy="0 0 0"/>
        <geometry>
            <sphere radius="0.01"/>
        </geometry>
        <material name="black"/>
    </visual>
    <collision>
        <origin xyz="0 0 0" rpy="0 0 0"/>
        <geometry>
            <sphere radius="0.01"/>
        </geometry>
    </collision>
    <xacro:inertial_sphere mass="0.05" radius="0.01">
        <origin xyz="0 0 0" rpy="0 0 0"/>
    </xacro:inertial_sphere>
</link>

<joint name="back_left_upper_leg_joint" type="revolute">
    <parent link="back_left_hip"/>
    <child link="back_left_upper_leg"/>
    <origin xyz="0 0 0" rpy="${pi/2} 0 0"/>
    <axis xyz="0 0 1"/>
    <limit lower="${3*pi/4}" upper="${5*pi/4}" effort="0.1" velocity="0.1"/>
</joint>

<link name="back_left_upper_leg">
    <visual>
        <origin xyz="0.0 0.1 0.0"/>
        <geometry>
            <box size="0.13 0.3 0.08"/>
        </geometry>
        <material name="teal"/>
    </visual>
    <collision>
        <origin xyz="0.0 0.1 0.0"/>
        <geometry>
            <box size="0.13 0.3 0.08"/>
        </geometry>
    </collision>
    <xacro:inertial_box mass="0.3" x="0.13" y="0.3" z="0.08">
        <origin xyz="0.0 0.1 0.0" rpy="0 0 0"/>
    </xacro:inertial_box>
</link>

<joint name="back_left_lower_leg_joint" type="revolute">
    <parent link="back_left_upper_leg"/>
    <child link="back_left_lower_leg"/>
    <origin xyz="0 0.25 0" rpy="0 0 0"/>
    <axis xyz="0 0 1"/>
    <limit lower="${3*pi/4}" upper="${5*pi/4}" effort="0.1" velocity="0.1"/>
</joint>

<link name="back_left_lower_leg">
    <visual>
        <origin xyz="0 -0.1 0"/>
        <geometry>
            <box size="0.13 0.3 0.08"/>
        </geometry>
        <material name="teal"/>
    </visual>
    <collision>
        <origin xyz="0 -0.1 0"/>
        <geometry>
            <box size="0.13 0.3 0.08"/>
        </geometry>
    </collision>
    <xacro:inertial_box mass="0.3" x="0.13" y="0.3" z="0.08">
        <origin xyz="0.0 -0.1 0.0" rpy="0 0 0"/>
    </xacro:inertial_box>
</link>

<joint name="back_left_foot_joint" type="fixed">
    <parent link="back_left_lower_leg"/>
    <child link="back_left_foot"/>
    <origin xyz="0 -0.28 0"/>
</joint>

<link name="back_left_foot">
    <visual>
        <origin xyz="0 0 0"/>
        <geometry>
            <sphere radius="0.07"/>
        </geometry>
        <material name="black"/>
    </visual>
    <collision>
        <origin xyz="0 0 0"/>
        <geometry>
            <sphere radius="0.07"/>
        </geometry>
    </collision>
    <xacro:inertial_sphere mass="0.1" radius="0.07">
        <origin xyz="0 0 0" rpy="0 0 0"/>
    </xacro:inertial_sphere>
</link>


<!-- BACK RIGHT LEG -->
<joint name="back_right_hip_joint" type="revolute">
    <parent link="base_link"/>
    <child link="back_right_hip"/>
    <origin xyz="-0.3 -0.25 0.1" rpy="${pi/2} 0 0"/>
    <axis xyz="1 0 0"/>
    <limit lower="${3*pi/2}" upper="${5*pi/4}" effort="0.1" velocity="0.1"/>
</joint>

<link name="back_right_hip">
    <visual>
        <origin xyz="0 0 0" rpy="0 0 0"/>
        <geometry>
            <sphere radius="0.01"/>
        </geometry>
        <material name="black"/>
    </visual>
    <collision>
        <origin xyz="0 0 0" rpy="0 0 0"/>
        <geometry>
            <sphere radius="0.01"/>
        </geometry>
    </collision>
    <xacro:inertial_sphere mass="0.05" radius="0.01">
        <origin xyz="0 0 0" rpy="0 0 0"/>
    </xacro:inertial_sphere>
</link>

<joint name="back_right_upper_leg_joint" type="revolute">
    <parent link="back_right_hip"/>
    <child link="back_right_upper_leg"/>
    <origin xyz="0 0 0" rpy="${pi/2} 0 0"/>
    <axis xyz="0 0 1"/>
    <limit lower="${3*pi/4}" upper="${5*pi/4}" effort="0.1" velocity="0.1"/>
</joint>

<link name="back_right_upper_leg">
    <visual>
        <origin xyz="0.0 0.1 0.0"/>
        <geometry>
            <box size="0.13 0.3 0.08"/>
        </geometry>
        <material name="teal"/>
    </visual>
    <collision>
        <origin xyz="0.0 0.1 0.0"/>
        <geometry>
            <box size="0.13 0.3 0.08"/>
        </geometry>
    </collision>
    <xacro:inertial_box mass="0.3" x="0.13" y="0.3" z="0.08">
        <origin xyz="0.0 0.1 0.0" rpy="0 0 0"/>
    </xacro:inertial_box>
</link>

<joint name="back_right_lower_leg_joint" type="revolute">
    <parent link="back_right_upper_leg"/>
    <child link="back_right_lower_leg"/>
    <origin xyz="0 0.25 0" rpy="0 0 0"/>
    <axis xyz="0 0 1"/>
    <limit lower="${3*pi/4}" upper="${5*pi/4}" effort="0.1" velocity="0.1"/>
</joint>

<link name="back_right_lower_leg">
    <visual>
        <origin xyz="0 -0.1 0"/>
        <geometry>
            <box size="0.13 0.3 0.08"/>
        </geometry>
        <material name="teal"/>
    </visual>
    <collision>
        <origin xyz="0 -0.1 0"/>
        <geometry>
            <box size="0.13 0.3 0.08"/>
        </geometry>
        <material name="teal"/>
    </collision>
    <xacro:inertial_box mass="0.3" x="0.13" y="0.3" z="0.08">
        <origin xyz="0.0 -0.1 0.0" rpy="0 0 0"/>
    </xacro:inertial_box>
</link>

<joint name="back_right_foot_joint" type="fixed">
    <parent link="back_right_lower_leg"/>
    <child link="back_right_foot"/>
    <origin xyz="0 -0.28 0"/>
</joint>

<link name="back_right_foot">
    <visual>
        <origin xyz="0 0 0"/>
        <geometry>
            <sphere radius="0.07"/>
        </geometry>
        <material name="black"/>
    </visual>
    <collision>
        <origin xyz="0 0 0"/>
        <geometry>
            <sphere radius="0.07"/>
        </geometry>
    </collision>
    <xacro:inertial_sphere mass="0.1" radius="0.07">
        <origin xyz="0 0 0" rpy="0 0 0"/>
    </xacro:inertial_sphere>
</link>

<!-- FRONT LEFT LEG -->
<joint name="front_left_hip_joint" type="revolute">
    <parent link="base_link"/>
    <child link="front_left_hip"/>
    <origin xyz="0.3 0.25 0.1" rpy="${pi/2} 0 0"/>
    <axis xyz="-1 0 0"/>
    <limit lower="${pi/2}" upper="${pi/4}" effort="0.1" velocity="0.1"/>
</joint>

<link name="front_left_hip">
    <visual>
        <origin xyz="0 0 0" rpy="0 0 0"/>
        <geometry>
            <sphere radius="0.01"/>
        </geometry>
        <material name="black"/>
    </visual>
    <collision>
        <origin xyz="0 0 0" rpy="0 0 0"/>
        <geometry>
            <sphere radius="0.01"/>
        </geometry>
    </collision>
    <xacro:inertial_sphere mass="0.05" radius="0.01">
        <origin xyz="0 0 0" rpy="0 0 0"/>
    </xacro:inertial_sphere>
</link>

<joint name="front_left_upper_leg_joint" type="revolute">
    <parent link="front_left_hip"/>
    <child link="front_left_upper_leg"/>
    <origin xyz="0 0 0" rpy="${pi/2} 0 0"/>
    <axis xyz="0 0 -1"/>
    <limit lower="${3*pi/4}" upper="${5*pi/4}" effort="0.1" velocity="0.1"/>
</joint>

<link name="front_left_upper_leg">
    <visual>
        <origin xyz="0.0 0.1 0.0"/>
        <geometry>
            <box size="0.13 0.3 0.08"/>
        </geometry>
        <material name="teal"/>
    </visual>
    <collision>
        <origin xyz="0.0 0.1 0.0"/>
        <geometry>
            <box size="0.13 0.3 0.08"/>
        </geometry>
    </collision>
    <xacro:inertial_box mass="0.3" x="0.13" y="0.3" z="0.08">
        <origin xyz="0.0 0.1 0.0" rpy="0 0 0"/>
    </xacro:inertial_box>
</link>

<joint name="front_left_lower_leg_joint" type="revolute">
    <parent link="front_left_upper_leg"/>
    <child link="front_left_lower_leg"/>
    <origin xyz="0 0.25 0" rpy="0 0 0"/>
    <axis xyz="0 0 1"/>
    <limit lower="${3*pi/4}" upper="${5*pi/4}" effort="0.1" velocity="0.1"/>
</joint>

<link name="front_left_lower_leg">
    <visual>
        <origin xyz="0 -0.1 0"/>
        <geometry>
            <box size="0.13 0.3 0.08"/>
        </geometry>
        <material name="teal"/>
    </visual>
    <collision>
        <origin xyz="0 -0.1 0"/>
        <geometry>
            <box size="0.13 0.3 0.08"/>
        </geometry>
    </collision>
    <xacro:inertial_box mass="0.3" x="0.13" y="0.3" z="0.08">
        <origin xyz="0.0 -0.1 0.0" rpy="0 0 0"/>
    </xacro:inertial_box>
</link>

<joint name="front_left_foot_joint" type="fixed">
    <parent link="front_left_lower_leg"/>
    <child link="front_left_foot"/>
    <origin xyz="0 -0.28 0"/>
</joint>

<link name="front_left_foot">
    <visual>
        <origin xyz="0 0 0"/>
        <geometry>
            <sphere radius="0.07"/>
        </geometry>
        <material name="black"/>
    </visual>
    <collision>
        <origin xyz="0 0 0"/>
        <geometry>
            <sphere radius="0.07"/>
        </geometry>
    </collision>
    <xacro:inertial_sphere mass="0.1" radius="0.07">
        <origin xyz="0 0 0" rpy="0 0 0"/>
    </xacro:inertial_sphere>
</link>

<!-- FRONT RIGHT LEG -->
<joint name="front_right_hip_joint" type="revolute">
    <parent link="base_link"/>
    <child link="front_right_hip"/>
    <origin xyz="0.3 -0.25 0.1" rpy="${pi/2} 0 0"/>
    <axis xyz="1 0 0"/>
    <limit lower="${3*pi/2}" upper="${5*pi/4}" effort="0.1" velocity="0.1"/>
</joint>

<link name="front_right_hip">
    <visual>
        <origin xyz="0 0 0" rpy="0 0 0"/>
        <geometry>
            <sphere radius="0.01"/>
        </geometry>
        <material name="black"/>
    </visual>
    <collision>
        <origin xyz="0 0 0" rpy="0 0 0"/>
        <geometry>
            <sphere radius="0.01"/>
        </geometry>
    </collision>
    <xacro:inertial_sphere mass="0.05" radius="0.01">
        <origin xyz="0 0 0" rpy="0 0 0"/>
    </xacro:inertial_sphere>
</link>

<joint name="front_right_upper_leg_joint" type="revolute">
    <parent link="front_right_hip"/>
    <child link="front_right_upper_leg"/>
    <origin xyz="0 0 0" rpy="${pi/2} 0 0"/>
    <axis xyz="0 0 -1"/>
    <limit lower="${3*pi/4}" upper="${5*pi/4}" effort="0.1" velocity="0.1"/>
</joint>

<link name="front_right_upper_leg">
    <visual>
        <origin xyz="0.0 0.1 0.0"/>
        <geometry>
            <box size="0.13 0.3 0.08"/>
        </geometry>
        <material name="teal"/>
    </visual>
    <collision>
        <origin xyz="0.0 0.1 0.0"/>
        <geometry>
            <box size="0.13 0.3 0.08"/>
        </geometry>
    </collision>
    <xacro:inertial_box mass="0.3" x="0.13" y="0.3" z="0.08">
        <origin xyz="0.0 0.1 0.0" rpy="0 0 0"/>
    </xacro:inertial_box>
</link>

<joint name="front_right_lower_leg_joint" type="revolute">
    <parent link="front_right_upper_leg"/>
    <child link="front_right_lower_leg"/>
    <origin xyz="0 0.25 0" rpy="0 0 0"/>
    <axis xyz="0 0 1"/>
    <limit lower="${3*pi/4}" upper="${5*pi/4}" effort="0.1" velocity="0.1"/>
</joint>

<link name="front_right_lower_leg">
    <visual>
        <origin xyz="0 -0.1 0"/>
        <geometry>
            <box size="0.13 0.3 0.08"/>
        </geometry>
        <material name="teal"/>
    </visual>
    <collision>
        <origin xyz="0 -0.1 0"/>
        <geometry>
            <box size="0.13 0.3 0.08"/>
        </geometry>
    </collision>
    <xacro:inertial_box mass="0.3" x="0.13" y="0.3" z="0.08">
        <origin xyz="0.0 -0.1 0.0" rpy="0 0 0"/>
    </xacro:inertial_box>
</link>

<joint name="front_right_foot_joint" type="fixed">
    <parent link="front_right_lower_leg"/>
    <child link="front_right_foot"/>
    <origin xyz="0 -0.28 0"/>
</joint>

<link name="front_right_foot">
    <visual>
        <origin xyz="0 0 0"/>
        <geometry>
            <sphere radius="0.07"/>
        </geometry>
        <material name="black"/>
    </visual>
    <collision>
        <origin xyz="0 0 0"/>
        <geometry>
            <sphere radius="0.07"/>
        </geometry>
    </collision>
    <xacro:inertial_sphere mass="0.1" radius="0.07">
        <origin xyz="0 0 0" rpy="0 0 0"/>
    </xacro:inertial_sphere>
</link>

</robot>